<?xml version="1.0"?>

<!-- DO NOT EDIT: Generated from nxp_drone.sdf.jinja -->
<sdf version='1.6'>
  <model name='mantis'>
    <pose>0 0 0 0 0 0</pose>
    <self_collide>false</self_collide>
    <static>false</static>
    <link name="base_link">
      <inertial>
        <mass>0.572</mass>
        <inertia>
          <ixx>0.0013218</ixx>
          <iyy>0.00058023</iyy>
          <izz>0.0013443</izz>

        </inertia>
      </inertial>
      <gravity>true</gravity>
      <self_collide>false</self_collide>
      <velocity_decay/>
      <visual name="base_link_visual">
        <pose>0 0 0.015 0 0 0</pose>
        <geometry>
          <mesh>
            <scale>1 1 1</scale>
            <uri>model://mantis/meshes/base_link_new.dae</uri>
          </mesh>
        </geometry>
                <material>
          <script>
            <name>Gazebo/DarkGrey</name>
            <uri>file://media/materials/scripts/gazebo.material</uri>
          </script>
        </material>

      </visual>
      
      <collision name="base_link_collision_0">
        <pose>0 0 0.015 0 0 0</pose>
        <geometry>
          <box>
            <size>0.22 0.22 0.14</size>
          </box>
        </geometry>
        <surface>
          <contact>
            <ode>
              <min_depth>0.001</min_depth>
              <max_vel>0</max_vel>
            </ode>
          </contact>
          <friction>
            <ode/>
          </friction>
        </surface>
      </collision>

      <sensor name='cameracolor' type='camera'>
        <camera name='camera'>
          <horizontal_fov>1</horizontal_fov>
          <image>
            <width>1</width>
            <height>1</height>
            <format>RGB_INT8</format>
          </image>
          <clip>
            <near>0.1</near>
            <far>100</far>
          </clip>
          <noise>
            <type>gaussian</type>
            <mean>0</mean>
            <stddev>0</stddev>
            <!--<stddev>0.007</stddev>-->
          </noise>
        </camera>
        <always_on>1</always_on>
        <update_rate>0</update_rate>
        <visualize>0</visualize>
        <pose frame=''>0.055 0.0325 0.05 0 -0 0</pose>
      </sensor>
      <sensor name='cameraired1' type='camera'>
        <camera name='camera'>
          <!--<horizontal_fov>1.48702</horizontal_fov>-->
          <horizontal_fov>1</horizontal_fov>
          <vertical_fov>1</vertical_fov>
          <image>
            <width>848</width> <!--1280-->
            <height>480</height> <!--720-->
            <format>L_INT8</format>
          </image>
          <clip>
            <near>0.1</near>
            <far>100</far>
          </clip>
          <noise>
            <type>gaussian</type>
            <mean>0</mean>
            <stddev>0.0</stddev><!--0.05-->
          </noise>
        </camera>
        <always_on>1</always_on>
        <update_rate>90</update_rate>
        <visualize>0</visualize>
        <pose frame=''>0.055 0.0175 0.05 0 -0 0</pose>
      </sensor>
      <sensor name='cameraired2' type='camera'>
        <camera name='camera'>
          <!--<horizontal_fov>1.48702</horizontal_fov>-->
          <horizontal_fov>1</horizontal_fov>
          <vertical_fov>1</vertical_fov>
          <image>
            <width>848</width> <!--1280-->
            <height>480</height> <!--720-->
            <format>L_INT8</format>
          </image>
          <clip>
            <near>0.1</near>
            <far>100</far>
          </clip>
          <noise>
            <type>gaussian</type>
            <mean>0</mean>
            <stddev>0.0</stddev><!--0.05-->
          </noise>
        </camera>
        <always_on>1</always_on>
        <update_rate>90</update_rate>
        <visualize>0</visualize>
        <pose frame=''>0.055 -0.0375 0.05 0 -0 0</pose>
      </sensor>
      <sensor name='cameradepth' type='depth'>
        <camera name='camera'>
          <horizontal_fov>1.48702</horizontal_fov>
          <image>
            <width>1</width>
            <height>1</height>
          </image>
          <clip>
            <near>0.1</near>
            <far>100</far>
          </clip>
          <noise>
            <type>gaussian</type>
            <mean>0</mean>
            <stddev>0.1</stddev>
          </noise>
        </camera>
        <always_on>1</always_on>
        <update_rate>1</update_rate>
        <visualize>0</visualize>
        <pose frame=''>0 0.0175 0.05 0 -0 0</pose>
      </sensor>

    </link>
          <parent>base_link</parent>

    <link name='nxp_drone/imu_link'>
      <pose>0 0 0 0 0 0</pose>
      <inertial>
        <pose>0 0 0 0 0 0</pose>
        <mass>0.001</mass>
        <inertia>
          <ixx>1e-08</ixx>
          <ixy>0</ixy>
          <ixz>0</ixz>
          <iyy>1e-08</iyy>
          <iyz>0</iyz>
          <izz>1e-08</izz>
        </inertia>
      </inertial>
    </link>
    <joint name='imu_nxp_drone_joint' type='revolute'>
      <child>nxp_drone/imu_link</child>
      <parent>base_link</parent>
      <axis>
        <xyz>1 0 0</xyz>
        <limit>
          <lower>0</lower>
          <upper>0</upper>
          <effort>0</effort>
          <velocity>0</velocity>
        </limit>
        <dynamics>
          <spring_reference>0</spring_reference>
          <spring_stiffness>0</spring_stiffness>
        </dynamics>
        <use_parent_model_frame>1</use_parent_model_frame>
      </axis>
    </joint>

    <!--Rotor 0 -->
    <link name="rotor_0">
      <gravity>true</gravity>
      <self_collide>false</self_collide>
      <velocity_decay/>
      <pose>0.06 -0.06 -0.01 0 0 0</pose>
      <inertial>
          <mass>0.00165</mass>
          <inertia>
            <ixx>0.000000596</ixx>
            <iyy>0.000000596</iyy>
            <izz>0.000001191</izz>
          </inertia>
        </inertial>
      <visual name="rotor_0_visual">
        <pose>-0.01 -0.06653846153 -0.00909090909 0 0 0</pose>
        <geometry>
          <mesh>
            <scale>0.38461538461 0.38461538461 0.38461538461</scale>
            <uri>model://nxp_drone/meshes/1345_prop_ccw.stl</uri>
          </mesh>
        </geometry>
        <material>
          <script>
            <name>Gazebo/DarkGrey</name>
            <uri>file://media/materials/scripts/gazebo.material</uri>
          </script>
        </material>
      </visual>
      <!--<visual name="rotor_0_visual_motor_top">
        <pose>-.025 -.025 -0.042 0 0 0</pose>
        <geometry>
          <mesh>
            <scale>1 1 1</scale>
            <uri>model://nxp_drone/meshes/5010Top.stl</uri>
          </mesh>
        </geometry>
        <material>
          <script>
            <name>Gazebo/Grey</name>
            <uri>file://media/materials/scripts/gazebo.material</uri>
          </script>
        </material>
      </visual>
      <visual name="rotor_0_visual_motor_bottom">
        <pose>0 0 -0.024 0 0 0</pose>
        <geometry>
          <cylinder>
            <radius>0.025</radius>
            <length>0.01</length>
          </cylinder>
        </geometry>
        <material>
          <script>
            <name>Gazebo/Black</name>
            <uri>file://media/materials/scripts/gazebo.material</uri>
          </script>
        </material>
      </visual>-->
      <collision name="rotor_0_collision">
        <pose>0 0 0 0 0 0 </pose>
        <geometry>
          <box>
            <size>0.07 0.01 0.0008461538461538462</size>
          </box>
        </geometry>
        <surface>
          <contact>
            <ode>
              <min_depth>0.001</min_depth>
              <max_vel>0</max_vel>
            </ode>
          </contact>
          <friction>
            <ode/>
          </friction>
        </surface>
      </collision>
      
    </link>
    <joint name="rotor_0_joint" type="revolute">
      <parent>base_link</parent>
      <child>rotor_0</child>
      <axis>
        <xyz>0 0 1</xyz>
        <limit>
          <lower>-1e+16</lower>
          <upper>1e+16</upper>
        </limit>
        <dynamics>
          <spring_reference>0</spring_reference>
          <spring_stiffness>0</spring_stiffness>
        </dynamics>
        <use_parent_model_frame>1</use_parent_model_frame>
      </axis>
    </joint>
    <plugin name='rotor_0_motor_model' filename='libgazebo_motor_model.so'>
      <robotNamespace></robotNamespace>
      <jointName>rotor_0_joint</jointName>
      <linkName>rotor_0</linkName>
      <turningDirection>ccw</turningDirection>
      <!--<timeConstantUp>0.0043</timeConstantUp>
      <timeConstantDown>0.0043</timeConstantDown>-->
      <!--<timeConstantUp>0.1</timeConstantUp>
      <timeConstantDown>0.02</timeConstantDown>-->
      <timeConstantUp>0.0001</timeConstantUp>
      <timeConstantDown>0.0001</timeConstantDown>
      <maxRotVelocity>4000</maxRotVelocity>
      <motorConstant>0.00000025</motorConstant>
      <momentConstant>0.0031830988618379067</momentConstant>
      <commandSubTopic>/gazebo/command/motor_speed</commandSubTopic>
      <motorNumber>0</motorNumber>
      <rotorDragCoefficient>4.1119046519702394e-05</rotorDragCoefficient>
      <rollingMomentCoefficient>1e-06</rollingMomentCoefficient>
      <motorSpeedPubTopic>/motor_speed/0</motorSpeedPubTopic>
      <rotorVelocitySlowdownSim>10</rotorVelocitySlowdownSim>
    </plugin>
    
      
      
      
      

      
        
        
        
      

      

    <!--Rotor 1 -->
    <link name="rotor_1">
      <gravity>true</gravity>
      <self_collide>false</self_collide>
      <velocity_decay/>
      <pose>-0.06 0.06 -0.01 0 0 0</pose>
      <inertial>
          <mass>0.00165</mass>
          <inertia>
            <ixx>0.000000596</ixx>
            <iyy>0.000000596</iyy>
            <izz>0.000001191</izz>
          </inertia>
        </inertial>
      <visual name="rotor_1_visual">
        <pose>-0.01 -0.06653846153 -0.00909090909 0 0 0</pose>
        <geometry>
          <mesh>
            <scale>0.38461538461 0.38461538461 0.38461538461</scale>
            <uri>model://nxp_drone/meshes/1345_prop_ccw.stl</uri>
          </mesh>
        </geometry>
        <material>
          <script>
            <name>Gazebo/DarkGrey</name>
            <uri>file://media/materials/scripts/gazebo.material</uri>
          </script>
        </material>
      </visual>
      <!--<visual name="rotor_1_visual_motor_top">
        <pose>-.025 -.025 -0.042 0 0 0</pose>
        <geometry>
          <mesh>
            <scale>1 1 1</scale>
            <uri>model://nxp_drone/meshes/5010Top.stl</uri>
          </mesh>
        </geometry>
        <material>
          <script>
            <name>Gazebo/Grey</name>
            <uri>file://media/materials/scripts/gazebo.material</uri>
          </script>
        </material>
      </visual>-->
      <!--<visual name="rotor_1_visual_motor_bottom">
        <pose>0 0 -0.024 0 0 0</pose>
        <geometry>
          <cylinder>
            <radius>0.025</radius>
            <length>0.01</length>
          </cylinder>
        </geometry>
        <material>
          <script>
            <name>Gazebo/Black</name>
            <uri>file://media/materials/scripts/gazebo.material</uri>
          </script>
        </material>
      </visual>-->
      <collision name="rotor_1_collision">
        <pose>0 0 0 0 0 0 </pose>
        <geometry>
          <box>
            <size>0.07 0.01 0.0008461538461538462</size>
          </box>
        </geometry>
        <surface>
          <contact>
            <ode>
              <min_depth>0.001</min_depth>
              <max_vel>0</max_vel>
            </ode>
          </contact>
          <friction>
            <ode/>
          </friction>
        </surface>
      </collision>
    </link>
    <joint name="rotor_1_joint" type="revolute">
      <parent>base_link</parent>
      <child>rotor_1</child>
      <axis>
        <xyz>0 0 1</xyz>
        <limit>
          <lower>-1e+16</lower>
          <upper>1e+16</upper>
        </limit>
        <dynamics>
          <spring_reference>0</spring_reference>
          <spring_stiffness>0</spring_stiffness>
        </dynamics>
        <use_parent_model_frame>1</use_parent_model_frame>
      </axis>
    </joint>
    <plugin name='rotor_1_motor_model' filename='libgazebo_motor_model.so'>
      <robotNamespace></robotNamespace>
      <jointName>rotor_1_joint</jointName>
      <linkName>rotor_1</linkName>
      <turningDirection>ccw</turningDirection>
      <!--<timeConstantUp>0.0043</timeConstantUp>
      <timeConstantDown>0.0043</timeConstantDown>-->
      <!--<timeConstantUp>0.1</timeConstantUp>
      <timeConstantDown>0.02</timeConstantDown>-->
      <timeConstantUp>0.0001</timeConstantUp>
      <timeConstantDown>0.0001</timeConstantDown>
      <maxRotVelocity>4000</maxRotVelocity>
      <motorConstant>0.00000025</motorConstant>
      <momentConstant>0.0031830988618379067</momentConstant>
      <commandSubTopic>/gazebo/command/motor_speed</commandSubTopic>
      <motorNumber>1</motorNumber>
      <rotorDragCoefficient>4.1119046519702394e-05</rotorDragCoefficient>
      <rollingMomentCoefficient>1e-06</rollingMomentCoefficient>
      <motorSpeedPubTopic>/motor_speed/1</motorSpeedPubTopic>
      <rotorVelocitySlowdownSim>10</rotorVelocitySlowdownSim>
    </plugin>
    
      
      
      
      

      
        
        
        
      

      

    <!--Rotor 2 -->
    <link name="rotor_2">
      <gravity>true</gravity>
      <self_collide>false</self_collide>
      <velocity_decay/>
      <pose>0.06 0.06 -0.01 0 0 0</pose>
      <inertial>
               <mass>0.00165</mass>
          <inertia>
            <ixx>0.000000596</ixx>
            <iyy>0.000000596</iyy>
            <izz>0.000001191</izz>
          </inertia>
        </inertial>
      <visual name="rotor_2_visual">
        <pose>-0.01 -0.06653846153 -0.00909090909 0 0 0</pose>
        <geometry>
          <mesh>
            <scale>0.38461538461 0.38461538461 0.38461538461</scale>
            <uri>model://nxp_drone/meshes/1345_prop_cw.stl</uri>
          </mesh>
        </geometry>
        <material>
          <script>
            <name>Gazebo/DarkGrey</name>
            <uri>file://media/materials/scripts/gazebo.material</uri>
          </script>
        </material>
      </visual>
      <!--
      <visual name="rotor_2_visual_motor_top">
        <pose>-.025 -.025 -0.042 0 0 0</pose>
        <geometry>
          <mesh>
            <lscae>1 1 1</scale>
            <uri>model://nxp_drone/meshes/5010Top.stl</uri>
          </mesh>
        </geometry>
        <material>
          <script>
            <name>Gazebo/Grey</name>
            <uri>file://media/materials/scripts/gazebo.material</uri>
          </script>
        </material>
      </visual>
      <visual name="rotor_2_visual_motor_bottom">
        <pose>0 0 -0.024 0 0 0</pose>
        <geometry>
          <cylinder>
            <radius>0.025</radius>
            <length>0.01</length>
          </cylinder>
        </geometry>
        <material>
          <script>
            <name>Gazebo/Black</name>
            <uri>file://media/materials/scripts/gazebo.material</uri>
          </script>
        </material>
      </visual>-->
      <collision name="rotor_2_collision">
        <pose>0 0 0 0 0 0 </pose>
        <geometry>
          <box>
            <size>0.07 0.01 0.0008461538461538462</size>
          </box>
        </geometry>
        <surface>
          <contact>
            <ode>
              <min_depth>0.001</min_depth>
              <max_vel>0</max_vel>
            </ode>
          </contact>
          <friction>
            <ode/>
          </friction>
        </surface>
      </collision>
    </link>
    <joint name="rotor_2_joint" type="revolute">
      <parent>base_link</parent>
      <child>rotor_2</child>
      <axis>
        <xyz>0 0 1</xyz>
        <limit>
          <lower>-1e+16</lower>
          <upper>1e+16</upper>
        </limit>
        <dynamics>
          <spring_reference>0</spring_reference>
          <spring_stiffness>0</spring_stiffness>
        </dynamics>
        <use_parent_model_frame>1</use_parent_model_frame>
      </axis>
    </joint>
    <plugin name='rotor_2_motor_model' filename='libgazebo_motor_model.so'>
      <robotNamespace></robotNamespace>
      <jointName>rotor_2_joint</jointName>
      <linkName>rotor_2</linkName>
      <turningDirection>cw</turningDirection>
      <!--<timeConstantUp>0.0043</timeConstantUp>
      <timeConstantDown>0.0043</timeConstantDown>-->
      <!--<timeConstantUp>0.1</timeConstantUp>
      <timeConstantDown>0.02</timeConstantDown>-->
      <timeConstantUp>0.0001</timeConstantUp>
      <timeConstantDown>0.0001</timeConstantDown>
      <maxRotVelocity>4000</maxRotVelocity>
      <motorConstant>0.00000025</motorConstant>
      <momentConstant>0.0031830988618379067</momentConstant>
      <commandSubTopic>/gazebo/command/motor_speed</commandSubTopic>
      <motorNumber>2</motorNumber>
      <rotorDragCoefficient>4.1119046519702394e-05</rotorDragCoefficient>
      <rollingMomentCoefficient>1e-06</rollingMomentCoefficient>
      <motorSpeedPubTopic>/motor_speed/2</motorSpeedPubTopic>
      <rotorVelocitySlowdownSim>10</rotorVelocitySlowdownSim>
    </plugin>
    
      
      
      
      

      
        
        
        
      

      

    <!--Rotor 3 -->
    <link name="rotor_3">
      <gravity>true</gravity>
      <self_collide>false</self_collide>
      <velocity_decay/>
      <pose>-0.06 -0.06 -0.01 0 0 0</pose>
      <inertial>
          <mass>0.00165</mass>
          <inertia>
            <ixx>0.000000596</ixx>
            <iyy>0.000000596</iyy>
            <izz>0.000001191</izz>
          </inertia>
        </inertial>
      <visual name="rotor_3_visual">
        <pose>-0.01 -0.06653846153 -0.00909090909 0 0 0</pose>
        <geometry>
          <mesh>
            <scale>0.38461538461 0.38461538461 0.38461538461</scale>
            <uri>model://nxp_drone/meshes/1345_prop_cw.stl</uri>
          </mesh>
        </geometry>
        <material>
          <script>
            <name>Gazebo/DarkGrey</name>
            <uri>file://media/materials/scripts/gazebo.material</uri>
          </script>
        </material>
      </visual>
      <!--<visual name="rotor_3_visual_motor_top">
        <pose>-.025 -.025 -0.042 0 0 0</pose>
        <geometry>
          <mesh>
            <scale>1 1 1</scale>
            <uri>model://nxp_drone/meshes/5010Top.stl</uri>
          </mesh>
        </geometry>
        <material>
          <script>
            <name>Gazebo/Grey</name>
            <uri>file://media/materials/scripts/gazebo.material</uri>
          </script>
        </material>
      </visual>
      <visual name="rotor_3_visual_motor_bottom">
        <pose>0 0 -0.024 0 0 0</pose>
        <geometry>
          <cylinder>
            <radius>0.025</radius>
            <length>0.01</length>
          </cylinder>
        </geometry>
        <material>
          <script>
            <name>Gazebo/Black</name>
            <uri>file://media/materials/scripts/gazebo.material</uri>
          </script>
        </material>
      </visual>-->
      <collision name="rotor_3_collision">
        <pose>0 0 0 0 0 0 </pose>
        <geometry>
          <box>
            <size>0.07 0.01 0.0008461538461538462</size>
          </box>
        </geometry>
        <surface>
          <contact>
            <ode>
              <min_depth>0.001</min_depth>
              <max_vel>0</max_vel>
            </ode>
          </contact>
          <friction>
            <ode/>
          </friction>
        </surface>
      </collision>
    </link>
    <joint name="rotor_3_joint" type="revolute">
      <parent>base_link</parent>
      <child>rotor_3</child>
      <axis>
        <xyz>0 0 1</xyz>
        <limit>
          <lower>-1e+16</lower>
          <upper>1e+16</upper>
        </limit>
        <dynamics>
          <spring_reference>0</spring_reference>
          <spring_stiffness>0</spring_stiffness>
        </dynamics>
        <use_parent_model_frame>1</use_parent_model_frame>
      </axis>
    </joint>
    <plugin name='rotor_3_motor_model' filename='libgazebo_motor_model.so'>
      <robotNamespace></robotNamespace>
      <jointName>rotor_3_joint</jointName>
      <linkName>rotor_3</linkName>
      <turningDirection>cw</turningDirection>
      <!--<timeConstantUp>0.0043</timeConstantUp>
      <timeConstantDown>0.0043</timeConstantDown>-->
      <!--<timeConstantUp>0.1</timeConstantUp>
      <timeConstantDown>0.02</timeConstantDown>-->
      <timeConstantUp>0.0001</timeConstantUp>
      <timeConstantDown>0.0001</timeConstantDown>
      <maxRotVelocity>4000</maxRotVelocity>
      <motorConstant>0.00000025</motorConstant>
      <momentConstant>0.0031830988618379067</momentConstant>
      <commandSubTopic>/gazebo/command/motor_speed</commandSubTopic>
      <motorNumber>3</motorNumber>
      <rotorDragCoefficient>4.1119046519702394e-05</rotorDragCoefficient>
      <rollingMomentCoefficient>1e-06</rollingMomentCoefficient>
      <motorSpeedPubTopic>/motor_speed/3</motorSpeedPubTopic>
      <rotorVelocitySlowdownSim>10</rotorVelocitySlowdownSim>
    </plugin>
    
    <include>
      <uri>model://gps</uri>
      <pose>0 0 0 0 0 0</pose>
      <name>gps0</name>
    </include>
    <joint name='gps0_joint' type='fixed'>
      <child>gps0::link</child>
      <parent>base_link</parent>
    </joint>
    <plugin name='groundtruth_plugin' filename='libgazebo_groundtruth_plugin.so'>
      <robotNamespace/>
    </plugin>
    <plugin name='magnetometer_plugin' filename='libgazebo_magnetometer_plugin.so'>
      <robotNamespace/>
      <pubRate>100</pubRate>
      <noiseDensity>0.0004</noiseDensity>
      <randomWalk>6.4e-06</randomWalk>
      <biasCorrelationTime>600</biasCorrelationTime>
      <magTopic>/mag</magTopic>
    </plugin>
    <plugin name='barometer_plugin' filename='libgazebo_barometer_plugin.so'>
      <robotNamespace/>
      <pubRate>50</pubRate>
      <baroTopic>/baro</baroTopic>
      <baroDriftPaPerSec>0</baroDriftPaPerSec>
    </plugin>
    <plugin name='mavlink_interface' filename='libgazebo_mavlink_interface.so'>
      <robotNamespace/>
      <imuSubTopic>/imu</imuSubTopic>
      <magSubTopic>/mag</magSubTopic>
      <baroSubTopic>/baro</baroSubTopic>
      <mavlink_addr>INADDR_ANY</mavlink_addr>
      <mavlink_udp_port>14560</mavlink_udp_port>
      <mavlink_tcp_port>4560</mavlink_tcp_port>
      <serialEnabled>0</serialEnabled>
      <serialDevice>/dev/ttyACM0</serialDevice>
      <baudRate>921600</baudRate>
      <qgc_addr>INADDR_ANY</qgc_addr>
      <qgc_udp_port>14550</qgc_udp_port>
      <sdk_addr>INADDR_ANY</sdk_addr>
      <sdk_udp_port>14540</sdk_udp_port>
      <hil_mode>0</hil_mode>
      <hil_state_level>0</hil_state_level>
      <send_vision_estimation>0</send_vision_estimation>
      <send_odometry>1</send_odometry>
      <enable_lockstep>0</enable_lockstep>
      <use_tcp>0</use_tcp>
      <motorSpeedCommandPubTopic>/gazebo/command/motor_speed</motorSpeedCommandPubTopic>
      <control_channels>
        <channel name='rotor1'>
          <input_index>0</input_index>
          <input_offset>0</input_offset>
          <input_scaling>3600</input_scaling>
          <zero_position_disarmed>0</zero_position_disarmed>
          <zero_position_armed>400</zero_position_armed>
          <joint_control_type>velocity</joint_control_type>
        </channel>
        <channel name='rotor2'>
          <input_index>1</input_index>
          <input_offset>0</input_offset>
          <input_scaling>3600</input_scaling>
          <zero_position_disarmed>0</zero_position_disarmed>
          <zero_position_armed>400</zero_position_armed>
          <joint_control_type>velocity</joint_control_type>
        </channel>
        <channel name='rotor3'>
          <input_index>2</input_index>
          <input_offset>0</input_offset>
          <input_scaling>3600</input_scaling>
          <zero_position_disarmed>0</zero_position_disarmed>
          <zero_position_armed>400</zero_position_armed>
          <joint_control_type>velocity</joint_control_type>
        </channel>
        <channel name='rotor4'>
          <input_index>3</input_index>
          <input_offset>0</input_offset>
          <input_scaling>3600</input_scaling>
          <zero_position_disarmed>0</zero_position_disarmed>
          <zero_position_armed>400</zero_position_armed>
          <joint_control_type>velocity</joint_control_type>
        </channel>
      </control_channels>
    </plugin>
    <static>0</static>
    <plugin name='gazebo_imu_plugin' filename='libgazebo_imu_plugin.so'>
      <robotNamespace/>
      <linkName>nxp_drone/imu_link</linkName>
      <imuTopic>/imu</imuTopic>
      <updateRate>250</updateRate>
      <gyroscopeNoiseDensity>0.00018665</gyroscopeNoiseDensity>
      <gyroscopeRandomWalk>3.8785e-05</gyroscopeRandomWalk>
      <gyroscopeBiasCorrelationTime>1000.0</gyroscopeBiasCorrelationTime>
      <gyroscopeTurnOnBiasSigma>0.0087</gyroscopeTurnOnBiasSigma>
      <accelerometerNoiseDensity>0.00186</accelerometerNoiseDensity>
      <accelerometerRandomWalk>0.006</accelerometerRandomWalk>
      <accelerometerBiasCorrelationTime>300.0</accelerometerBiasCorrelationTime>
      <accelerometerTurnOnBiasSigma>0.196</accelerometerTurnOnBiasSigma>
        
      <!--<gyroscopeNoiseDensity>0.0006</gyroscopeNoiseDensity>
      <gyroscopeRandomWalk>0.000003</gyroscopeRandomWalk>        
      <gyroscopeTurnOnBiasSigma>0.03</gyroscopeTurnOnBiasSigma>

      <accelerometerNoiseDensity>0.002</accelerometerNoiseDensity>
      <accelerometerRandomWalk>0.00002</accelerometerRandomWalk>
      <accelerometerTurnOnBiasSigma>0.1</accelerometerTurnOnBiasSigma>-->

      <!--<gyroscopeNoiseDensity>0.0</gyroscopeNoiseDensity>
      <gyroscopeRandomWalk>0.0</gyroscopeRandomWalk>        
      <gyroscopeTurnOnBiasSigma>0.0</gyroscopeTurnOnBiasSigma>
      <gyroscopeBiasCorrelationTime>0.0</gyroscopeBiasCorrelationTime>
      
      <accelerometerNoiseDensity>0.0</accelerometerNoiseDensity>
      <accelerometerRandomWalk>0.0</accelerometerRandomWalk>
      <accelerometerTurnOnBiasSigma>0.0</accelerometerTurnOnBiasSigma>
      <accelerometerBiasCorrelationTime>0.0</accelerometerBiasCorrelationTime>-->
    </plugin>
  

    <plugin name='camera' filename='librealsense_gazebo_plugin.so'>
      <prefix>camera</prefix>
      <depthUpdateRate>0.0</depthUpdateRate>
      <colorUpdateRate>0.0</colorUpdateRate>
      <infraredUpdateRate>90.0</infraredUpdateRate>
      <depthTopicName>depth/image_raw</depthTopicName>
      <depthCameraInfoTopicName>depth/camera_info</depthCameraInfoTopicName>
      <colorTopicName>color/image_raw</colorTopicName>
      <colorCameraInfoTopicName>color/camera_info</colorCameraInfoTopicName>
      <infrared1TopicName>infra1/image_raw</infrared1TopicName>
      <infrared1CameraInfoTopicName>infra1/camera_info</infrared1CameraInfoTopicName>
      <infrared2TopicName>infra2/image_raw</infrared2TopicName>
      <infrared2CameraInfoTopicName>infra2/camera_info</infrared2CameraInfoTopicName>
      <colorOpticalframeName>camera_color_optical_frame</colorOpticalframeName>
      <depthOpticalframeName>camera_depth_optical_frame</depthOpticalframeName>
      <infrared1OpticalframeName>camera_left_ir_optical_frame</infrared1OpticalframeName>
      <infrared2OpticalframeName>camera_right_ir_optical_frame</infrared2OpticalframeName>
      <rangeMinDepth>0.2</rangeMinDepth>
      <rangeMaxDepth>10.0</rangeMaxDepth>
      <pointCloud>false</pointCloud>
      <pointCloudTopicName>depth/points</pointCloudTopicName>
      <pointCloudCutoff>0.5</pointCloudCutoff>
    </plugin>
  </model>
  </sdf>
